Workbook
Name Slicer_Account_Name: #N/A
Name Slicer_Created_Date: #N/A

Sheet Guidelines
A1: Report Name | B1: Billing Profile Change History
A2: Procedure | B2: - Extract the data from "Billing Profile Change History" report for the previous week
B3: - Run the cleanup macro which will highlight the potential errors and will verify the data
B4: - Check the fields Stylistic and Formatting (abbreviated words, punctuation, entity type formatting, etc.) as per "Account Creation Best Practices" Guidelines
B5: - Update the necessary changes in the records based on the audit
B6: - Visually check the records to see if any additional potential errors in the report
A8: Validation in fields levels
A9: Account Name | B9: Run a macro which identify potential error in Account name based on the standards (abbreviated words, punctuation, entity type formatting, etc.) also will check proper casing
A10: Account Street | B10: Run a macro which identify potential error in address field based on the standards (abbreviated words, punctuation, entity type formatting, etc.) also will check proper casing
A11: Account City | B11: Check proper casing in City field
A12: Account State/Province | B12: Check proper casing in State/Province field
A13: Account Country | B13: Check for US Territories AS, FM, GU, MH, MP, PW, PR, VI, UM and relocate to Billing state field
A14: Tax ID / VAT # | B14: Check the standard format (includes county code in VAT and blank for US country etc.) for Tax ID/VAT numbers alone If Deal Desk is inserting Tax IDs that aren't VAT/CNPJ/ABN/EFN #s it's fine to leave them in. I don't think it should cause any harm.
A15: Account Contact Name | B15: Check proper casing in Bill To Contact field

Sheet Audit_Description
A1: S.No. | B1: Audit Fields | C1: Description | D1: Formula Applied in the Account Profile Audit Sheet
A2: 1 | B2: Unique_Record_Flag | C2: Filter out unique records to avoid duplicate rows | D2: =IF(G2=G1,"","Unique Record")
A3: =A2+1 -> 2 | B3: Account_Upper Case_Flag | C3: Check the Account Name to see if the value is entered in the UPPER case. | D3: =IF(F2="","",IF(EXACT(F2,(UPPER(F2))),"Account Upper Case",""))
A4: =A3+1 -> 3 | B4: Account_Lower Case__Flag | C4: Check the Account Name to see if the value is entered in the LOWER case. | D4: =IF(F2="","",IF(EXACT(F2,(LOWER(F2))),"Account Lower Case",""))
A5: =A4+1 -> 4 | B5: Billing Street_ProperCase_Flag | C5: Billing Street: check if the value doesn’t enter in the PROPER case. | D5: =IF(EXACT(H2,PROPER(H2)),"","Billing Street - casing")
A6: =A5+1 -> 5 | B6: Billing City_ProperCase_Flag | C6: Billing City: check if the value doesn’t enter in the PROPER case. | D6: =IF(EXACT(I2,PROPER(I2)),"","City - casing")
A7: =A6+1 -> 6 | B7: Billing_City_Saint_Flag | C7: Saint abbreviation (St or St.) check in city | D7: =IF(OR(ISNUMBER(SEARCH("St.",I2)),ISNUMBER(SEARCH("St ",I2))),"Check St in city field",IF(RIGHT(I2,1)=".","Dot found in city field",""))
A8: =A7+1 -> 7 | B8: Billing_City_Special_Char_Flag | C8: Symbols check in City | D8: =IF((SUMPRODUCT(--ISNUMBER(SEARCH({"!","@","#","$","%","^","&","~*","(",")","_","+","=","{","}","[","]","|","\",":",";","'","""","<",">",",",".","~?","/","~~","`"}, I2)))>0)=TRUE,"Special Characters Found in City","")
A9: =A8+1 -> 8 | B9: Account_Special_Char_Flag | C9: Symbols check in Account | D9: =IF((SUMPRODUCT(--ISNUMBER(SEARCH({"!","@","#","$","%","^","~*","(",")","_","+","=","{","}","[","]","|","\",":",";","'","""","<",">","~?","/","~~","`"},F2)))>0)=TRUE,"Special Characters Found in Account field","")
A10: =A9+1 -> 9 | B10: Address1_Directionals_Flag | C10: Check the Directional Name to see if the value is entered in the abbreviated format. | D10: =IF(SUM(--ISNUMBER(SEARCH({1,2,3,4,5,6,7,8,9,0},MID(H2,(SEARCH(" E ",H2)-1),1))))+SUM(--ISNUMBER(SEARCH({1,2,3,4,5,6,7,8,9,0},MID(H2,(SEARCH(" E ",H2)+3),1))))=2,"",IF(SUM(--ISNUMBER(SEARCH({"Parte E","Apoquindo N"},H2)))>0,"",IF(OR(RIGHT(H2,3)=" NE",RIGHT(H2,3)=" NW",RIGHT(H2,3)=" SW",RIGHT(H2,3)=" SE",RIGHT(H2,2)=" N",RIGHT(H2,2)=" E",RIGHT(H2,2)=" W",RIGHT(H2,2)=" S",LEFT(H2,3)="NE ",LEFT(H2,3)="NW ",LEFT(H2,3)="SW ",LEFT(H2,3)="SE ",LEFT(H2,2)="N ",LEFT(H2,2)="E ",LEFT(H2,2)="W ",LEFT(H2,2)="S "),"Directional Check",IF(SUM(--ISNUMBER(SEARCH({" N "," E "," W "," S "," NE "," NW "," SW "," SE ","N.E","N.W","S.W","S.E","E.","N.","S.","W."},H2)))>0,"Directional Check",IF(SUM(--ISNUMBER(SEARCH({1,2,3,4,5,6,7,8,9,0},MID(H2,(SEARCH("nd ",H2)-1),1))))+SUM(--ISNUMBER(SEARCH({1,2,3,4,5,6,7,8,9,0},MID(H2,(SEARCH("rd ",H2)-1),1)))+SUM(--ISNUMBER(SEARCH({1,2,3,4,5,6,7,8,9,0},MID(H2,(SEARCH("st ",H2)-1),1))))+SUM(--ISNUMBER(SEARCH({1,2,3,4,5,6,7,8,9,0},MID(H2,(SEARCH("th ",H2)-1),1)))))>0,"","")))))
A11: =A10+1 -> 10 | B11: State_Code_Flag | C11: Check the State codes to see if the value is entered properly based on countries. (US, CA, BR and AU should have proper abbreviated codes.) | D11: =IF(IF(L2="US",IFERROR(VLOOKUP(J2,'Country Codes'!$B:$B,1,0)=J2,"US State Code Error"),IF(L2="CA",IFERROR(VLOOKUP(J2,'Country Codes'!$E:$E,1,0)=J2,"Canada State Code Error"),IF(L2="BR",IFERROR(VLOOKUP(J2,'Country Codes'!$H:$H,1,0)=J2,"Brazil State Code Error"),IF(L2="AU",IFERROR(VLOOKUP(J2,'Country Codes'!$K:$K,1,0)=J2,"Australia State Code Error"),""))))=TRUE,"",IF(L2="US",IFERROR(VLOOKUP(J2,'Country Codes'!$B:$B,1,0)=J2,"US State Code Error"),IF(L2="CA",IFERROR(VLOOKUP(J2,'Country Codes'!$E:$E,1,0)=J2,"Canada State Code Error"),IF(L2="BR",IFERROR(VLOOKUP(J2,'Country Codes'!$H:$H,1,0)=J2,"Brazil State Code Error"),IF(L2="AU",IFERROR(VLOOKUP(J2,'Country Codes'!$K:$K,1,0)=J2,"Australia State Code Error"),"")))))
A12: =A11+1 -> 11 | B12: State_Upper_Case_Flag | C12: Check the State codes to see if the value is entered UPPER case for the countries US, CA, BR & AU and all other countries should have proper case.) | D12: =IF(OR(L2="US",L2="CA",L2="BR",L2="AU"),IF((EXACT(UPPER(J2),J2)),"","Country Code Casing"),IF(EXACT(J2,PROPER(J2)),"","Billing State casing"))
A13: =A12+1 -> 12 | B13: Address_Flag | C13: Check the City/State/PO/Countries to see if the value are entered Address 1 field | D13: =IFERROR(IFS(IF(AND(LEN(I2)=0,ISBLANK(I2)=FALSE),"",ISNUMBER(SEARCH(I2,H2))),"City/Postal Code/Country Found in Address",IF(AND(LEN(K2)=0,ISBLANK(K2)=FALSE),"",ISNUMBER(SEARCH(K2,H2))),"City/Postal Code/Country Found in Address",IF(AND(LEN(L2)=0,ISBLANK(L2)=FALSE),"",ISNUMBER(SEARCH(", "&L2,H2))),"City/Postal Code/Country Found in Address",IF(AND(LEN(J2)=0,ISBLANK(J2)=FALSE),"",ISNUMBER(SEARCH(", "&J2,H2))),"City/Postal Code/Country Found in Address",IF(AND(LEN(L2)=0,ISBLANK(L2)=FALSE),"",ISNUMBER(SEARCH(","&L2,H2))),"City/Postal Code/Country Found in Address",IF(AND(LEN(J2)=0,ISBLANK(J2)=FALSE),"",ISNUMBER(SEARCH(","&J2,H2))),"City/Postal Code/Country Found in Address"),"")
A14: =A13+1 -> 13 | B14: Incorrect_TaxID_Field_Flag | C14: Check the PO Number to see if the value is entered in Tax ID field. | D14: =IF(ISNUMBER(SEARCH("PO",N2)),"PO# Entered in Tax ID Field","")
... A20: =A19+1 -> 19 | B20: Consolidate_Error_Remarks | C20: This field combines all the above errors as a single value to perform audit | D20: =IF(S2="","",S2&"; ")&IF(T2="","",T2&"; ")&IF(U2="","",U2&"; ")&IF(V2="","",V2&"; ")&IF(AF2="","",AF2&"; ")&IF(AG2="","",AG2&"; ")&IF(AH2="","",AH2&"; ")&IF(AL2="","",AL2&"; ")&IF(Z2="","",Z2&"; ")&IF(AA2="","",AA2&"; ")&IF(AB2="","",AB2&"; ")&IF(AC2="","",AC2&"; ")&IF(AD2="","",AD2&"; ")&IF(AE2="","",AE2&"; ")&IF(AJ2="","",AJ2&"; ")&IF(AK2="","",AK2&"; ")&IF(AI2="","",AI2&"; ")&IF(W2="","",W2&"; ")&IF(X2="","",X2&"; ")&IF(Y2="","",Y2&"; ")
A21: =A20+1 -> 20 | B21: Audited_Status | C21: Enter remarks once the audit is complete for the row

Sheet Dashboard
D3: =IFERROR("Source Quality "&TEXT(G7/D7,"##.00%"),"") -> Source Quality 98.82% | R3: Pivot Table
R5: Unique_Record_Flag | S5: Unique Record
D6: Total Records | G6: Clean Records | J6: Issue Records | M6: Avg. Issue/Rec
D7: =SUM(T9:T1048576)/2 -> 931 | G7: =(SUM(T9:T1048576)/2)-(SUM(U9:U1048576)/2) -> 920 | J7: =(SUM(U9:U1048576)/2) -> 11 | M7: =(AVERAGE(U9:U1048576)/2) -> 0.012557078 | T7: Values | AA7: Values
D8: Unique Records | G8: ="Percentage: " & TEXT((COUNTIFS(Account_Profile_Audit!$R:$R,"Unique Record",Account_Profile_Audit!AJ:AJ,"")/COUNTIFS(Account_Profile_Audit!$R:$R,"Unique Record")),"#.00%") -> Percentage: 98.93% | J8: ="Percentage: " & TEXT(J7/D7,"#.00%") -> Percentage: 1.18% | M8: ="Error ratio is "&IF(M7>=0.1,"High (✖)",IF(M7>=0.05,"Medium (⚠)","Low (!)")) -> Error ratio is Low (!) | R8: Created Date | S8: Account Name | T8: Count of Account ID | U8: Sum of Total | V8: Sum of Casing | W8: Sum of Abbreviation | X8: Sum of Incorrect | Y8: Sum of Format | AA8: -Casing | AB8: 5
R9: 45315 | S9: Sample flow, inc. | T9: 4 | U9: 1 | V9: 1 | W9: 0 | X9: 0 | Y9: 0 | AA9: -Incorrect | AB9: 4
R10: 45423 | S10: SampleCo Partners | T10: 1 | U10: 0 | V10: 0 | W10: 0 | X10: 0 | Y10: 0 | AA10: -Format | AB10: 2
R11: 45424 | S11: Sample Ltd | T11: 1 | U11: 0 | V11: 0 | W11: 0 | X11: 0 | Y11: 0 | AA11: -Abbreviation | AB11: 1
R12: 45424 | S12: SampleCo, Inc. | T12: 1 | U12: 0 | V12: 0 | W12: 0 | X12: 0 | Y12: 0
R13: 45424 | S13: SampleCorp Ltd | T13: 1 | U13: 0 | V13: 0 | W13: 0 | X13: 0 | Y13: 0
R14: 45425 | S14: Sample Technologies, Inc. | T14: 1 | U14: 0 | V14: 0 | W14: 0 | X14: 0 | Y14: 0
R15: 45425 | S15: SampleCorp Technologies, Inc. | T15: 1 | U15: 0 | V15: 0 | W15: 0 | X15: 0 | Y15: 0
R16: 45426 | S16: Sample Ltd | T16: 1 | U16: 0 | V16: 0 | W16: 0 | X16: 0 | Y16: 0
R17: 45426 | S17: SampleCo Technologies, Inc. | T17: 2 | U17: 0 | V17: 0 | W17: 0 | X17: 0 | Y17: 0
R18: 45426 | S18: SampleCorp Technologies, Inc. | T18: 1 | U18: 0 | V18: 0 | W18: 0 | X18: 0 | Y18: 0
R19: 45427 | S19: SampleCorp Products, Inc. | T19: 1 | U19: 0 | V19: 0 | W19: 0 | X19: 0 | Y19: 0
R20: 45428 | S20: SampleCo Partners | T20: 1 | U20: 0 | V20: 0 | W20: 0 | X20: 0 | Y20: 0
R21: 45428 | S21: SampleCorp Partners | T21: 1 | U21: 0 | V21: 0 | W21: 0 | X21: 0 | Y21: 0
R22: 45428 | S22: SampleCorp Technologies, Inc. | T22: 1 | U22: 0 | V22: 0 | W22: 0 | X22: 0 | Y22: 0
R23: 45429 | S23: Sample Products, Inc. | T23: 2 | U23: 0 | V23: 0 | W23: 0 | X23: 0 | Y23: 0
... R883: 46149 | S883: SampleCorp Technologies, Inc. | T883: 1 | U883: 0 | V883: 0 | W883: 0 | X883: 0 | Y883: 0
R884: Grand Total | T884: 931 | U884: 11 | V884: 5 | W884: 1 | X884: 4 | Y884: 1

Sheet Account_Profile_Audit
A1: CRM Change History Report | Q1: - | R1: - | S1: Casing | T1: Casing | U1: Casing | V1: Casing | W1: Abbreviation | X1: Format | Y1: Format | Z1: Abbreviation | AA1: Incorrect | AB1: Casing | AC1: Incorrect | AD1: Incorrect | AE1: Incorrect | AF1: Format | AG1: Casing | AH1: Incorrect | AI1: Incorrect | AJ1: - | AK1: - | AL1: Error Category | AV1: Created Date | AW1: Account Name
A2: Created Date | B2: Created By | C2: Field | D2: Original Value | E2: New Value | F2: Account Name | G2: Account ID | H2: Billing Street | I2: Billing City | J2: Billing State/Province | K2: Billing Zip/Postal Code | L2: Billing Country | M2: PO Number | N2: Tax ID / VAT # | O2: Bill To Contact | P2: Billing Contact Name | Q2: - | R2: Unique_Record_Flag | S2: Account_Upper Case_Flag | T2: Account_Lower Case__Flag | U2: Billing Street_ProperCase_Flag | V2: Billing City_ProperCase_Flag | W2: Billing_City_Saint_Flag | X2: Billing_City_Special_Char_Flag | Y2: Account_Special_Char_Flag | Z2: Address1_Directionals_Flag | AA2: State_Code_Flag | AB2: State_Upper_Case_Flag | AC2: Address_Flag | AD2: Incorrect_TaxID_Field_Flag | AE2: Incorrect_PO#_Flag | AF2: Tax ID_VAT_Validation | AG2: Contact_ProperCase_Flag | AH2: US_Territories_Flag | AI2: Country_Code_Flag | AJ2: Consolidate_Error_Remarks | AK2: Audited_Status | AL2: - | AM2: Casing | AN2: Abbreviation | AO2: Incorrect | AP2: Format | AQ2: Total | AS2: Error Category | AT2: Cout | AV2: All | AW2: All
A3: 45590 | B3: User 1 | C3: PO Number | D3: PO-007496 | E3: PO-017004 | F3: Sample, Inc. | G3: ID_Num_1 | H3: Suite 30000A, Street | I3: bozeman | J3: MT | K3: 59715 | L3: US | M3: PO-017 | P3: Accounts Payable | R3: =IF(G3=G2,"","Unique Record") -> Unique Record | S3: =IF(F3="","",IF(EXACT(F3,(UPPER(F3))),"Account Upper Case","")) | T3: =IF(F3="","",IF(EXACT(F3,(LOWER(F3))),"Account Lower Case","")) | U3: =IF(EXACT(H3,PROPER(H3)),"","Billing Street - casing") | V3: =IF(EXACT(I3,PROPER(I3)),"","City - casing") -> City - casing | W3: =IF(OR(ISNUMBER(SEARCH("East",I3)),ISNUMBER(SEARCH("West",I3)),ISNUMBER(SEARCH("North",I3)),ISNUMBER(SEARCH("South",I3))),"",IF(OR(ISNUMBER(SEARCH("St.",I3)),ISNUMBER(SEARCH("St ",I3))),"Check St in city field",IF(RIGHT(I3,1)=".","Dot found in city field",""))) | X3: {=IF((SUMPRODUCT(--ISNUMBER(SEARCH({"!","@","#","$","%","^","&","~*","(",")","_","+","=","{","}","[","]","|","\",":",";","'","""","<",">",",",".","~?","/","~~","`"}, I3)))>0)=TRUE,"Special Characters Found in City","")} | Y3: {=IF((SUMPRODUCT(--ISNUMBER(SEARCH({"!","@","#","$","%","^","~*","(",")","_","+","=","{","}","[","]","|","\",":",";","'","""","<",">","~?","/","~~","`"},F3)))>0)=TRUE,"Special Characters Found in Account field","")} | Z3: {=IF(SUM(--ISNUMBER(SEARCH({1,2,3,4,5,6,7,8,9,0},MID(H3,(SEARCH(" E ",H3)-1),1))))+SUM(--ISNUMBER(SEARCH({1,2,3,4,5,6,7,8,9,0},MID(H3,(SEARCH(" E ",H3)+3),1))))=2,"",IF(SUM(--ISNUMBER(SEARCH({"Parte E","Apoquindo N"},H3)))>0,"",IF(OR(RIGHT(H3,3)=" NE",RIGHT(H3,3)=" NW",RIGHT(H3,3)=" SW",RIGHT(H3,3)=" SE",RIGHT(H3,2)=" N",RIGHT(H3,2)=" E",RIGHT(H3,2)=" W",RIGHT(H3,2)=" S",LEFT(H3,3)="NE ",LEFT(H3,3)="NW ",LEFT(H3,3)="SW ",LEFT(H3,3)="SE ",LEFT(H3,2)="N ",LEFT(H3,2)="E ",LEFT(H3,2)="W ",LEFT(H3,2)="S "),"Directional Check",IF(SUM(--ISNUMBER(SEARCH({" N "," E "," W "," S "," NE "," NW "," SW "," SE ","N.E","N.W","S.W","S.E","E.","N.","S.","W."},H3)))>0,"Directional Check",IF(SUM(--ISNUMBER(SEARCH({1,2,3,4,5,6,7,8,9,0},MID(H3,(SEARCH("nd ",H3)-1),1))))+SUM(--ISNUMBER(SEARCH({1,2,3,4,5,6,7,8,9,0},MID(H3,(SEARCH("rd ",H3)-1),1)))+SUM(--ISNUMBER(SEARCH({1,2,3,4,5,6,7,8,9,0},MID(H3,(SEARCH("st ",H3)-1),1))))+SUM(--ISNUMBER(SEARCH({1,2,3,4,5,6,7,8,9,0},MID(H3,(SEARCH("th ",H3)-1),1)))))>0,"","")))))} | AA3: =IF(IF(L3="US",IFERROR(VLOOKUP(J3,Country_Codes!$B:$B,1,0)=J3,"US State Code Error"),IF(L3="CA",IFERROR(VLOOKUP(J3,Country_Codes!$E:$E,1,0)=J3,"Canada State Code Error"),IF(L3="BR",IFERROR(VLOOKUP(J3,Country_Codes!$H:$H,1,0)=J3,"Brazil State Code Error"),IF(L3="AU",IFERROR(VLOOKUP(J3,Country_Codes!$K:$K,1,0)=J3,"Australia State Code Error"),""))))=TRUE,"",IF(L3="US",IFERROR(VLOOKUP(J3,Country_Codes!$B:$B,1,0)=J3,"US State Code Error"),IF(L3="CA",IFERROR(VLOOKUP(J3,Country_Codes!$E:$E,1,0)=J3,"Canada State Code Error"),IF(L3="BR",IFERROR(VLOOKUP(J3,Country_Codes!$H:$H,1,0)=J3,"Brazil State Code Error"),IF(L3="AU",IFERROR(VLOOKUP(J3,Country_Codes!$K:$K,1,0)=J3,"Australia State Code Error"),""))))) | AB3: =IF(OR(L3="US",L3="CA",L3="BR",L3="AU"),IF((EXACT(UPPER(J3),J3)),"","Country Code Casing"),IF(EXACT(J3,PROPER(J3)),"","Billing State casing")) | AC3: {=IFERROR(_xlfn.IFS(IF(AND(LEN(I3)=0,ISBLANK(I3)=FALSE),"",ISNUMBER(SEARCH(I3,H3))),"City/Postal Code/Country Found in Address",IF(AND(LEN(K3)=0,ISBLANK(K3)=FALSE),"",ISNUMBER(SEARCH(K3,H3))),"City/Postal Code/Country Found in Address",IF(AND(LEN(L3)=0,ISBLANK(L3)=FALSE),"",ISNUMBER(SEARCH(", "&L3,H3))),"City/Postal Code/Country Found in Address",IF(AND(LEN(J3)=0,ISBLANK(J3)=FALSE),"",ISNUMBER(SEARCH(", "&J3,H3))),"City/Postal Code/Country Found in Address",IF(AND(LEN(L3)=0,ISBLANK(L3)=FALSE),"",ISNUMBER(SEARCH(","&L3,H3))),"City/Postal Code/Country Found in Address",IF(AND(LEN(J3)=0,ISBLANK(J3)=FALSE),"",ISNUMBER(SEARCH(","&J3,H3))),"City/Postal Code/Country Found in Address"),"")} | AD3: =IF(ISNUMBER(SEARCH("PO",N3)),"PO# Entered in Tax ID Field","") | AE3: {=IFERROR(IF(VLOOKUP(LEFT(M3,MIN(SEARCH({1,2,3,4,5,6,7,8,9,0},M3&{1,2,3,4,5,6,7,8,9,0}))-1),Country_Codes!$N:$N,1,0)>0,"PO Number may be incorrect",""),"")} | AF3: =IF(N3="","",IF(EXACT(L3,LEFT(N3,2)),IF(EXACT(MID(N3,3,1)," "),"Check the Space inbetween County code & VAT",""),"Check the VAT Country Code Format")) | AG3: =IF((ISNUMBER(SEARCH("@",P3)))>0,"",IF(IF(--(ISNUMBER(SEARCH("'",P3)))>0,OR(EXACT(PROPER(P3),P3),EXACT((PROPER(LEFT(P3,FIND("'",P3)-2))&LOWER(MID(P3,FIND("'",P3)-1,1))&PROPER(MID(P3,FIND("'",P3)+0,LEN(P3)-FIND("'",P3)+1))),P3)),"Please check Billing Contact Casing")=TRUE,"","Please check Billing Contact casing")) | AH3: =IF(OR(L3="AS",L3="FM",L3="GU",L3="MH",L3="MP",L3="PW",L3="PR",L3="VI",L3="UM"),"US Territories Check","") | AI3: {=IF(G3="","",_xlfn.IFNA(_xlfn.IFS(L3=VLOOKUP(L3,Country_Codes!$M:$M,1,0)=TRUE,""),"Please check the country code"))} | AJ3: =IF(S3="","",S3&"; ")&IF(T3="","",T3&"; ")&IF(U3="","",U3&"; ")&IF(V3="","",V3&"; ")&IF(AF3="","",AF3&"; ")&IF(AG3="","",AG3&"; ")&IF(AH3="","",AH3&"; ")&IF(Z3="","",Z3&"; ")&IF(AA3="","",AA3&"; ")&IF(AB3="","",AB3&"; ")&IF(AC3="","",AC3&"; ")&IF(AD3="","",AD3&"; ")&IF(AE3="","",AE3&"; ")&IF(AI3="","",AI3&"; ")&IF(W3="","",W3&"; ")&IF(X3="","",X3&"; ")&IF(Y3="","",Y3&"; ") -> City - casing; | AM3: =(COUNTA(S3:V3)-COUNTIFS((S3:V3),""))+(COUNTA(AB3)-COUNTIFS((AB3),""))+(COUNTA(AG3)-COUNTIFS((AG3),"")) -> 1 | AN3: =(COUNTA(W3)-COUNTIFS((W3),""))+(COUNTA(Z3)-COUNTIFS((Z3),"")) -> 0 | AO3: =(COUNTA(AA3)-COUNTIFS((AA3),""))+(COUNTA(AC3:AE3)-COUNTIFS((AC3:AE3),""))+(COUNTA(AH3:AI3)-COUNTIFS((AH3:AI3),"")) -> 0 | AP3: =(COUNTA(X3:Y3)-COUNTIFS((X3:Y3),""))+(COUNTA(AF3)-COUNTIFS((AF3),"")) -> 0 | AQ3: =SUM(AM3:AP3) -> 1 | AS3: Casing | AT3: =SUM($AM:$AM) -> 5 | AV3: {=_xlfn._xlws.SORT(_xlfn.UNIQUE(A4:A1047),,1)} -> 45315 | AW3: {=_xlfn._xlws.SORT(_xlfn.UNIQUE(F4:F1047),,1)} -> Sample flow, inc.
A4: 45594 | B4: User 1 | C4: Account Name | D4: Sample Inc. | E4: Sample, Inc. | F4: Sample, Inc. | G4: ID_Num_1 | H4: Suite 30000A, Street | I4: Bozeman | J4: MT | K4: 59715 | L4: US | M4: PO-017 | P4: Accounts Payable | R4: =IF(G4=G3,"","Unique Record") | S4: =IF(F4="","",IF(EXACT(F4,(UPPER(F4))),"Account Upper Case","")) | T4: =IF(F4="","",IF(EXACT(F4,(LOWER(F4))),"Account Lower Case","")) | U4: =IF(EXACT(H4,PROPER(H4)),"","Billing Street - casing") | V4: =IF(EXACT(I4,PROPER(I4)),"","City - casing") | W4: =IF(OR(ISNUMBER(SEARCH("East",I4)),ISNUMBER(SEARCH("West",I4)),ISNUMBER(SEARCH("North",I4)),ISNUMBER(SEARCH("South",I4))),"",IF(OR(ISNUMBER(SEARCH("St.",I4)),ISNUMBER(SEARCH("St ",I4))),"Check St in city field",IF(RIGHT(I4,1)=".","Dot found in city field",""))) | X4: {=IF((SUMPRODUCT(--ISNUMBER(SEARCH({"!","@","#","$","%","^","&","~*","(",")","_","+","=","{","}","[","]","|","\",":",";","'","""","<",">",",",".","~?","/","~~","`"}, I4)))>0)=TRUE,"Special Characters Found in City","")} | Y4: {=IF((SUMPRODUCT(--ISNUMBER(SEARCH({"!","@","#","$","%","^","~*","(",")","_","+","=","{","}","[","]","|","\",":",";","'","""","<",">","~?","/","~~","`"},F4)))>0)=TRUE,"Special Characters Found in Account field","")} | Z4: {=IF(SUM(--ISNUMBER(SEARCH({1,2,3,4,5,6,7,8,9,0},MID(H4,(SEARCH(" E ",H4)-1),1))))+SUM(--ISNUMBER(SEARCH({1,2,3,4,5,6,7,8,9,0},MID(H4,(SEARCH(" E ",H4)+3),1))))=2,"",IF(SUM(--ISNUMBER(SEARCH({"Parte E","Apoquindo N"},H4)))>0,"",IF(OR(RIGHT(H4,3)=" NE",RIGHT(H4,3)=" NW",RIGHT(H4,3)=" SW",RIGHT(H4,3)=" SE",RIGHT(H4,2)=" N",RIGHT(H4,2)=" E",RIGHT(H4,2)=" W",RIGHT(H4,2)=" S",LEFT(H4,3)="NE ",LEFT(H4,3)="NW ",LEFT(H4,3)="SW ",LEFT(H4,3)="SE ",LEFT(H4,2)="N ",LEFT(H4,2)="E ",LEFT(H4,2)="W ",LEFT(H4,2)="S "),"Directional Check",IF(SUM(--ISNUMBER(SEARCH({" N "," E "," W "," S "," NE "," NW "," SW "," SE ","N.E","N.W","S.W","S.E","E.","N.","S.","W."},H4)))>0,"Directional Check",IF(SUM(--ISNUMBER(SEARCH({1,2,3,4,5,6,7,8,9,0},MID(H4,(SEARCH("nd ",H4)-1),1))))+SUM(--ISNUMBER(SEARCH({1,2,3,4,5,6,7,8,9,0},MID(H4,(SEARCH("rd ",H4)-1),1)))+SUM(--ISNUMBER(SEARCH({1,2,3,4,5,6,7,8,9,0},MID(H4,(SEARCH("st ",H4)-1),1))))+SUM(--ISNUMBER(SEARCH({1,2,3,4,5,6,7,8,9,0},MID(H4,(SEARCH("th ",H4)-1),1)))))>0,"","")))))} | AA4: =IF(IF(L4="US",IFERROR(VLOOKUP(J4,Country_Codes!$B:$B,1,0)=J4,"US State Code Error"),IF(L4="CA",IFERROR(VLOOKUP(J4,Country_Codes!$E:$E,1,0)=J4,"Canada State Code Error"),IF(L4="BR",IFERROR(VLOOKUP(J4,Country_Codes!$H:$H,1,0)=J4,"Brazil State Code Error"),IF(L4="AU",IFERROR(VLOOKUP(J4,Country_Codes!$K:$K,1,0)=J4,"Australia State Code Error"),""))))=TRUE,"",IF(L4="US",IFERROR(VLOOKUP(J4,Country_Codes!$B:$B,1,0)=J4,"US State Code Error"),IF(L4="CA",IFERROR(VLOOKUP(J4,Country_Codes!$E:$E,1,0)=J4,"Canada State Code Error"),IF(L4="BR",IFERROR(VLOOKUP(J4,Country_Codes!$H:$H,1,0)=J4,"Brazil State Code Error"),IF(L4="AU",IFERROR(VLOOKUP(J4,Country_Codes!$K:$K,1,0)=J4,"Australia State Code Error"),""))))) | AB4: =IF(OR(L4="US",L4="CA",L4="BR",L4="AU"),IF((EXACT(UPPER(J4),J4)),"","Country Code Casing"),IF(EXACT(J4,PROPER(J4)),"","Billing State casing")) | AC4: {=IFERROR(_xlfn.IFS(IF(AND(LEN(I4)=0,ISBLANK(I4)=FALSE),"",ISNUMBER(SEARCH(I4,H4))),"City/Postal Code/Country Found in Address",IF(AND(LEN(K4)=0,ISBLANK(K4)=FALSE),"",ISNUMBER(SEARCH(K4,H4))),"City/Postal Code/Country Found in Address",IF(AND(LEN(L4)=0,ISBLANK(L4)=FALSE),"",ISNUMBER(SEARCH(", "&L4,H4))),"City/Postal Code/Country Found in Address",IF(AND(LEN(J4)=0,ISBLANK(J4)=FALSE),"",ISNUMBER(SEARCH(", "&J4,H4))),"City/Postal Code/Country Found in Address",IF(AND(LEN(L4)=0,ISBLANK(L4)=FALSE),"",ISNUMBER(SEARCH(","&L4,H4))),"City/Postal Code/Country Found in Address",IF(AND(LEN(J4)=0,ISBLANK(J4)=FALSE),"",ISNUMBER(SEARCH(","&J4,H4))),"City/Postal Code/Country Found in Address"),"")} | AD4: =IF(ISNUMBER(SEARCH("PO",N4)),"PO# Entered in Tax ID Field","") | AE4: {=IFERROR(IF(VLOOKUP(LEFT(M4,MIN(SEARCH({1,2,3,4,5,6,7,8,9,0},M4&{1,2,3,4,5,6,7,8,9,0}))-1),Country_Codes!$N:$N,1,0)>0,"PO Number may be incorrect",""),"")} | AF4: =IF(N4="","",IF(EXACT(L4,LEFT(N4,2)),IF(EXACT(MID(N4,3,1)," "),"Check the Space inbetween County code & VAT",""),"Check the VAT Country Code Format")) | AG4: =IF((ISNUMBER(SEARCH("@",P4)))>0,"",IF(IF(--(ISNUMBER(SEARCH("'",P4)))>0,OR(EXACT(PROPER(P4),P4),EXACT((PROPER(LEFT(P4,FIND("'",P4)-2))&LOWER(MID(P4,FIND("'",P4)-1,1))&PROPER(MID(P4,FIND("'",P4)+0,LEN(P4)-FIND("'",P4)+1))),P4)),"Please check Billing Contact Casing")=TRUE,"","Please check Billing Contact casing")) | AH4: =IF(OR(L4="AS",L4="FM",L4="GU",L4="MH",L4="MP",L4="PW",L4="PR",L4="VI",L4="UM"),"US Territories Check","") | AI4: {=IF(G4="","",_xlfn.IFNA(_xlfn.IFS(L4=VLOOKUP(L4,Country_Codes!$M:$M,1,0)=TRUE,""),"Please check the country code"))} | AJ4: =IF(S4="","",S4&"; ")&IF(T4="","",T4&"; ")&IF(U4="","",U4&"; ")&IF(V4="","",V4&"; ")&IF(AF4="","",AF4&"; ")&IF(AG4="","",AG4&"; ")&IF(AH4="","",AH4&"; ")&IF(Z4="","",Z4&"; ")&IF(AA4="","",AA4&"; ")&IF(AB4="","",AB4&"; ")&IF(AC4="","",AC4&"; ")&IF(AD4="","",AD4&"; ")&IF(AE4="","",AE4&"; ")&IF(AI4="","",AI4&"; ")&IF(W4="","",W4&"; ")&IF(X4="","",X4&"; ")&IF(Y4="","",Y4&"; ") | AM4: =(COUNTA(S4:V4)-COUNTIFS((S4:V4),""))+(COUNTA(AB4)-COUNTIFS((AB4),""))+(COUNTA(AG4)-COUNTIFS((AG4),"")) -> 0 | AN4: =(COUNTA(W4)-COUNTIFS((W4),""))+(COUNTA(Z4)-COUNTIFS((Z4),"")) -> 0 | AO4: =(COUNTA(AA4)-COUNTIFS((AA4),""))+(COUNTA(AC4:AE4)-COUNTIFS((AC4:AE4),""))+(COUNTA(AH4:AI4)-COUNTIFS((AH4:AI4),"")) -> 0 | AP4: =(COUNTA(X4:Y4)-COUNTIFS((X4:Y4),""))+(COUNTA(AF4)-COUNTIFS((AF4),"")) -> 0 | AQ4: =SUM(AM4:AP4) -> 0 | AS4: Incorrect | AT4: =SUM($AO:$AO) -> 4 | AV4: 45393 | AW4: Sample Ltd
A5: 45596 | B5: User 2 | C5: Bill To Contact | D5: ID-0001a000 | E5: ID-0002a000 | F5: SAMPLE PARTNERS | G5: ID_Num_2 | H5: 50000 N Street | I5: Dallas | J5: TX | K5: 75201 | L5: US | O5: Justin Frank | R5: =IF(G5=G4,"","Unique Record") -> Unique Record | S5: =IF(F5="","",IF(EXACT(F5,(UPPER(F5))),"Account Upper Case","")) -> Account Upper Case | T5: =IF(F5="","",IF(EXACT(F5,(LOWER(F5))),"Account Lower Case","")) | U5: =IF(EXACT(H5,PROPER(H5)),"","Billing Street - casing") | V5: =IF(EXACT(I5,PROPER(I5)),"","City - casing") | W5: =IF(OR(ISNUMBER(SEARCH("East",I5)),ISNUMBER(SEARCH("West",I5)),ISNUMBER(SEARCH("North",I5)),ISNUMBER(SEARCH("South",I5))),"",IF(OR(ISNUMBER(SEARCH("St.",I5)),ISNUMBER(SEARCH("St ",I5))),"Check St in city field",IF(RIGHT(I5,1)=".","Dot found in city field",""))) | X5: {=IF((SUMPRODUCT(--ISNUMBER(SEARCH({"!","@","#","$","%","^","&","~*","(",")","_","+","=","{","}","[","]","|","\",":",";","'","""","<",">",",",".","~?","/","~~","`"}, I5)))>0)=TRUE,"Special Characters Found in City","")} | Y5: {=IF((SUMPRODUCT(--ISNUMBER(SEARCH({"!","@","#","$","%","^","~*","(",")","_","+","=","{","}","[","]","|","\",":",";","'","""","<",">","~?","/","~~","`"},F5)))>0)=TRUE,"Special Characters Found in Account field","")} | Z5: {=IF(SUM(--ISNUMBER(SEARCH({1,2,3,4,5,6,7,8,9,0},MID(H5,(SEARCH(" E ",H5)-1),1))))+SUM(--ISNUMBER(SEARCH({1,2,3,4,5,6,7,8,9,0},MID(H5,(SEARCH(" E ",H5)+3),1))))=2,"",IF(SUM(--ISNUMBER(SEARCH({"Parte E","Apoquindo N"},H5)))>0,"",IF(OR(RIGHT(H5,3)=" NE",RIGHT(H5,3)=" NW",RIGHT(H5,3)=" SW",RIGHT(H5,3)=" SE",RIGHT(H5,2)=" N",RIGHT(H5,2)=" E",RIGHT(H5,2)=" W",RIGHT(H5,2)=" S",LEFT(H5,3)="NE ",LEFT(H5,3)="NW ",LEFT(H5,3)="SW ",LEFT(H5,3)="SE ",LEFT(H5,2)="N ",LEFT(H5,2)="E ",LEFT(H5,2)="W ",LEFT(H5,2)="S "),"Directional Check",IF(SUM(--ISNUMBER(SEARCH({" N "," E "," W "," S "," NE "," NW "," SW "," SE ","N.E","N.W","S.W","S.E","E.","N.","S.","W."},H5)))>0,"Directional Check",IF(SUM(--ISNUMBER(SEARCH({1,2,3,4,5,6,7,8,9,0},MID(H5,(SEARCH("nd ",H5)-1),1))))+SUM(--ISNUMBER(SEARCH({1,2,3,4,5,6,7,8,9,0},MID(H5,(SEARCH("rd ",H5)-1),1)))+SUM(--ISNUMBER(SEARCH({1,2,3,4,5,6,7,8,9,0},MID(H5,(SEARCH("st ",H5)-1),1))))+SUM(--ISNUMBER(SEARCH({1,2,3,4,5,6,7,8,9,0},MID(H5,(SEARCH("th ",H5)-1),1)))))>0,"","")))))} -> Directional Check | AA5: =IF(IF(L5="US",IFERROR(VLOOKUP(J5,Country_Codes!$B:$B,1,0)=J5,"US State Code Error"),IF(L5="CA",IFERROR(VLOOKUP(J5,Country_Codes!$E:$E,1,0)=J5,"Canada State Code Error"),IF(L5="BR",IFERROR(VLOOKUP(J5,Country_Codes!$H:$H,1,0)=J5,"Brazil State Code Error"),IF(L5="AU",IFERROR(VLOOKUP(J5,Country_Codes!$K:$K,1,0)=J5,"Australia State Code Error"),""))))=TRUE,"",IF(L5="US",IFERROR(VLOOKUP(J5,Country_Codes!$B:$B,1,0)=J5,"US State Code Error"),IF(L5="CA",IFERROR(VLOOKUP(J5,Country_Codes!$E:$E,1,0)=J5,"Canada State Code Error"),IF(L5="BR",IFERROR(VLOOKUP(J5,Country_Codes!$H:$H,1,0)=J5,"Brazil State Code Error"),IF(L5="AU",IFERROR(VLOOKUP(J5,Country_Codes!$K:$K,1,0)=J5,"Australia State Code Error"),""))))) | AB5: =IF(OR(L5="US",L5="CA",L5="BR",L5="AU"),IF((EXACT(UPPER(J5),J5)),"","Country Code Casing"),IF(EXACT(J5,PROPER(J5)),"","Billing State casing")) | AC5: {=IFERROR(_xlfn.IFS(IF(AND(LEN(I5)=0,ISBLANK(I5)=FALSE),"",ISNUMBER(SEARCH(I5,H5))),"City/Postal Code/Country Found in Address",IF(AND(LEN(K5)=0,ISBLANK(K5)=FALSE),"",ISNUMBER(SEARCH(K5,H5))),"City/Postal Code/Country Found in Address",IF(AND(LEN(L5)=0,ISBLANK(L5)=FALSE),"",ISNUMBER(SEARCH(", "&L5,H5))),"City/Postal Code/Country Found in Address",IF(AND(LEN(J5)=0,ISBLANK(J5)=FALSE),"",ISNUMBER(SEARCH(", "&J5,H5))),"City/Postal Code/Country Found in Address",IF(AND(LEN(L5)=0,ISBLANK(L5)=FALSE),"",ISNUMBER(SEARCH(","&L5,H5))),"City/Postal Code/Country Found in Address",IF(AND(LEN(J5)=0,ISBLANK(J5)=FALSE),"",ISNUMBER(SEARCH(","&J5,H5))),"City/Postal Code/Country Found in Address"),"")} | AD5: =IF(ISNUMBER(SEARCH("PO",N5)),"PO# Entered in Tax ID Field","") | AE5: {=IFERROR(IF(VLOOKUP(LEFT(M5,MIN(SEARCH({1,2,3,4,5,6,7,8,9,0},M5&{1,2,3,4,5,6,7,8,9,0}))-1),Country_Codes!$N:$N,1,0)>0,"PO Number may be incorrect",""),"")} | AF5: =IF(N5="","",IF(EXACT(L5,LEFT(N5,2)),IF(EXACT(MID(N5,3,1)," "),"Check the Space inbetween County code & VAT",""),"Check the VAT Country Code Format")) | AG5: =IF((ISNUMBER(SEARCH("@",P5)))>0,"",IF(IF(--(ISNUMBER(SEARCH("'",P5)))>0,OR(EXACT(PROPER(P5),P5),EXACT((PROPER(LEFT(P5,FIND("'",P5)-2))&LOWER(MID(P5,FIND("'",P5)-1,1))&PROPER(MID(P5,FIND("'",P5)+0,LEN(P5)-FIND("'",P5)+1))),P5)),"Please check Billing Contact Casing")=TRUE,"","Please check Billing Contact casing")) | AH5: =IF(OR(L5="AS",L5="FM",L5="GU",L5="MH",L5="MP",L5="PW",L5="PR",L5="VI",L5="UM"),"US Territories Check","") | AI5: {=IF(G5="","",_xlfn.IFNA(_xlfn.IFS(L5=VLOOKUP(L5,Country_Codes!$M:$M,1,0)=TRUE,""),"Please check the country code"))} | AJ5: =IF(S5="","",S5&"; ")&IF(T5="","",T5&"; ")&IF(U5="","",U5&"; ")&IF(V5="","",V5&"; ")&IF(AF5="","",AF5&"; ")&IF(AG5="","",AG5&"; ")&IF(AH5="","",AH5&"; ")&IF(Z5="","",Z5&"; ")&IF(AA5="","",AA5&"; ")&IF(AB5="","",AB5&"; ")&IF(AC5="","",AC5&"; ")&IF(AD5="","",AD5&"; ")&IF(AE5="","",AE5&"; ")&IF(AI5="","",AI5&"; ")&IF(W5="","",W5&"; ")&IF(X5="","",X5&"; ")&IF(Y5="","",Y5&"; ") -> Account Upper Case; Directional Check; | AM5: =(COUNTA(S5:V5)-COUNTIFS((S5:V5),""))+(COUNTA(AB5)-COUNTIFS((AB5),""))+(COUNTA(AG5)-COUNTIFS((AG5),"")) -> 1 | AN5: =(COUNTA(W5)-COUNTIFS((W5),""))+(COUNTA(Z5)-COUNTIFS((Z5),"")) -> 1 | AO5: =(COUNTA(AA5)-COUNTIFS((AA5),""))+(COUNTA(AC5:AE5)-COUNTIFS((AC5:AE5),""))+(COUNTA(AH5:AI5)-COUNTIFS((AH5:AI5),"")) -> 0 | AP5: =(COUNTA(X5:Y5)-COUNTIFS((X5:Y5),""))+(COUNTA(AF5)-COUNTIFS((AF5),"")) -> 0 | AQ5: =SUM(AM5:AP5) -> 2 | AS5: Format | AT5: =SUM($AP:$AP) -> 2 | AV5: 45419 | AW5: SAMPLE PARTNERS
A6: 45574 | B6: User 1 | C6: Bill To Contact | D6: ID-0003a000 | E6: ID-0004a000 | F6: Sample Products, Inc. | G6: ID_Num_3 | H6: 10000 Sample Court, Suite 200 | I6: Mississauga | J6: ON | K6: L5N 5R5 | L6: CA | M6: 5600004 | O6: Smith Frank | R6: =IF(G6=G5,"","Unique Record") -> Unique Record | S6: =IF(F6="","",IF(EXACT(F6,(UPPER(F6))),"Account Upper Case","")) | T6: =IF(F6="","",IF(EXACT(F6,(LOWER(F6))),"Account Lower Case","")) | U6: =IF(EXACT(H6,PROPER(H6)),"","Billing Street - casing") | V6: =IF(EXACT(I6,PROPER(I6)),"","City - casing") | W6: =IF(OR(ISNUMBER(SEARCH("East",I6)),ISNUMBER(SEARCH("West",I6)),ISNUMBER(SEARCH("North",I6)),ISNUMBER(SEARCH("South",I6))),"",IF(OR(ISNUMBER(SEARCH("St.",I6)),ISNUMBER(SEARCH("St ",I6))),"Check St in city field",IF(RIGHT(I6,1)=".","Dot found in city field",""))) | X6: {=IF((SUMPRODUCT(--ISNUMBER(SEARCH({"!","@","#","$","%","^","&","~*","(",")","_","+","=","{","}","[","]","|","\",":",";","'","""","<",">",",",".","~?","/","~~","`"}, I6)))>0)=TRUE,"Special Characters Found in City","")} | Y6: {=IF((SUMPRODUCT(--ISNUMBER(SEARCH({"!","@","#","$","%","^","~*","(",")","_","+","=","{","}","[","]","|","\",":",";","'","""","<",">","~?","/","~~","`"},F6)))>0)=TRUE,"Special Characters Found in Account field","")} | Z6: {=IF(SUM(--ISNUMBER(SEARCH({1,2,3,4,5,6,7,8,9,0},MID(H6,(SEARCH(" E ",H6)-1),1))))+SUM(--ISNUMBER(SEARCH({1,2,3,4,5,6,7,8,9,0},MID(H6,(SEARCH(" E ",H6)+3),1))))=2,"",IF(SUM(--ISNUMBER(SEARCH({"Parte E","Apoquindo N"},H6)))>0,"",IF(OR(RIGHT(H6,3)=" NE",RIGHT(H6,3)=" NW",RIGHT(H6,3)=" SW",RIGHT(H6,3)=" SE",RIGHT(H6,2)=" N",RIGHT(H6,2)=" E",RIGHT(H6,2)=" W",RIGHT(H6,2)=" S",LEFT(H6,3)="NE ",LEFT(H6,3)="NW ",LEFT(H6,3)="SW ",LEFT(H6,3)="SE ",LEFT(H6,2)="N ",LEFT(H6,2)="E ",LEFT(H6,2)="W ",LEFT(H6,2)="S "),"Directional Check",IF(SUM(--ISNUMBER(SEARCH({" N "," E "," W "," S "," NE "," NW "," SW "," SE ","N.E","N.W","S.W","S.E","E.","N.","S.","W."},H6)))>0,"Directional Check",IF(SUM(--ISNUMBER(SEARCH({1,2,3,4,5,6,7,8,9,0},MID(H6,(SEARCH("nd ",H6)-1),1))))+SUM(--ISNUMBER(SEARCH({1,2,3,4,5,6,7,8,9,0},MID(H6,(SEARCH("rd ",H6)-1),1)))+SUM(--ISNUMBER(SEARCH({1,2,3,4,5,6,7,8,9,0},MID(H6,(SEARCH("st ",H6)-1),1))))+SUM(--ISNUMBER(SEARCH({1,2,3,4,5,6,7,8,9,0},MID(H6,(SEARCH("th ",H6)-1),1)))))>0,"","")))))} | AA6: =IF(IF(L6="US",IFERROR(VLOOKUP(J6,Country_Codes!$B:$B,1,0)=J6,"US State Code Error"),IF(L6="CA",IFERROR(VLOOKUP(J6,Country_Codes!$E:$E,1,0)=J6,"Canada State Code Error"),IF(L6="BR",IFERROR(VLOOKUP(J6,Country_Codes!$H:$H,1,0)=J6,"Brazil State Code Error"),IF(L6="AU",IFERROR(VLOOKUP(J6,Country_Codes!$K:$K,1,0)=J6,"Australia State Code Error"),""))))=TRUE,"",IF(L6="US",IFERROR(VLOOKUP(J6,Country_Codes!$B:$B,1,0)=J6,"US State Code Error"),IF(L6="CA",IFERROR(VLOOKUP(J6,Country_Codes!$E:$E,1,0)=J6,"Canada State Code Error"),IF(L6="BR",IFERROR(VLOOKUP(J6,Country_Codes!$H:$H,1,0)=J6,"Brazil State Code Error"),IF(L6="AU",IFERROR(VLOOKUP(J6,Country_Codes!$K:$K,1,0)=J6,"Australia State Code Error"),""))))) | AB6: =IF(OR(L6="US",L6="CA",L6="BR",L6="AU"),IF((EXACT(UPPER(J6),J6)),"","Country Code Casing"),IF(EXACT(J6,PROPER(J6)),"","Billing State casing")) | AC6: {=IFERROR(_xlfn.IFS(IF(AND(LEN(I6)=0,ISBLANK(I6)=FALSE),"",ISNUMBER(SEARCH(I6,H6))),"City/Postal Code/Country Found in Address",IF(AND(LEN(K6)=0,ISBLANK(K6)=FALSE),"",ISNUMBER(SEARCH(K6,H6))),"City/Postal Code/Country Found in Address",IF(AND(LEN(L6)=0,ISBLANK(L6)=FALSE),"",ISNUMBER(SEARCH(", "&L6,H6))),"City/Postal Code/Country Found in Address",IF(AND(LEN(J6)=0,ISBLANK(J6)=FALSE),"",ISNUMBER(SEARCH(", "&J6,H6))),"City/Postal Code/Country Found in Address",IF(AND(LEN(L6)=0,ISBLANK(L6)=FALSE),"",ISNUMBER(SEARCH(","&L6,H6))),"City/Postal Code/Country Found in Address",IF(AND(LEN(J6)=0,ISBLANK(J6)=FALSE),"",ISNUMBER(SEARCH(","&J6,H6))),"City/Postal Code/Country Found in Address"),"")} | AD6: =IF(ISNUMBER(SEARCH("PO",N6)),"PO# Entered in Tax ID Field","") | AE6: {=IFERROR(IF(VLOOKUP(LEFT(M6,MIN(SEARCH({1,2,3,4,5,6,7,8,9,0},M6&{1,2,3,4,5,6,7,8,9,0}))-1),Country_Codes!$N:$N,1,0)>0,"PO Number may be incorrect",""),"")} | AF6: =IF(N6="","",IF(EXACT(L6,LEFT(N6,2)),IF(EXACT(MID(N6,3,1)," "),"Check the Space inbetween County code & VAT",""),"Check the VAT Country Code Format")) | AG6: =IF((ISNUMBER(SEARCH("@",P6)))>0,"",IF(IF(--(ISNUMBER(SEARCH("'",P6)))>0,OR(EXACT(PROPER(P6),P6),EXACT((PROPER(LEFT(P6,FIND("'",P6)-2))&LOWER(MID(P6,FIND("'",P6)-1,1))&PROPER(MID(P6,FIND("'",P6)+0,LEN(P6)-FIND("'",P6)+1))),P6)),"Please check Billing Contact Casing")=TRUE,"","Please check Billing Contact casing")) | AH6: =IF(OR(L6="AS",L6="FM",L6="GU",L6="MH",L6="MP",L6="PW",L6="PR",L6="VI",L6="UM"),"US Territories Check","") | AI6: {=IF(G6="","",_xlfn.IFNA(_xlfn.IFS(L6=VLOOKUP(L6,Country_Codes!$M:$M,1,0)=TRUE,""),"Please check the country code"))} | AJ6: =IF(S6="","",S6&"; ")&IF(T6="","",T6&"; ")&IF(U6="","",U6&"; ")&IF(V6="","",V6&"; ")&IF(AF6="","",AF6&"; ")&IF(AG6="","",AG6&"; ")&IF(AH6="","",AH6&"; ")&IF(Z6="","",Z6&"; ")&IF(AA6="","",AA6&"; ")&IF(AB6="","",AB6&"; ")&IF(AC6="","",AC6&"; ")&IF(AD6="","",AD6&"; ")&IF(AE6="","",AE6&"; ")&IF(AI6="","",AI6&"; ")&IF(W6="","",W6&"; ")&IF(X6="","",X6&"; ")&IF(Y6="","",Y6&"; ") | AM6: =(COUNTA(S6:V6)-COUNTIFS((S6:V6),""))+(COUNTA(AB6)-COUNTIFS((AB6),""))+(COUNTA(AG6)-COUNTIFS((AG6),"")) -> 0 | AN6: =(COUNTA(W6)-COUNTIFS((W6),""))+(COUNTA(Z6)-COUNTIFS((Z6),"")) -> 0 | AO6: =(COUNTA(AA6)-COUNTIFS((AA6),""))+(COUNTA(AC6:AE6)-COUNTIFS((AC6:AE6),""))+(COUNTA(AH6:AI6)-COUNTIFS((AH6:AI6),"")) -> 0 | AP6: =(COUNTA(X6:Y6)-COUNTIFS((X6:Y6),""))+(COUNTA(AF6)-COUNTIFS((AF6),"")) -> 0 | AQ6: =SUM(AM6:AP6) -> 0 | AS6: Abbreviation | AT6: =SUM($AN:$AN) -> 1 | AV6: 45423 | AW6: Sample Products, Inc.
A7: 45393 | B7: User 3 | C7: PO Number | D7: 3587 | E7: 4490 | F7: Sample Products, Inc. | G7: ID_Num_3 | H7: 10000 Sample Court, Suite 200 | I7: Mississauga | J7: ON | K7: L5N 5R5 | L7: CA | M7: 5600004 | O7: Smith Frank | R7: =IF(G7=G6,"","Unique Record") | S7: =IF(F7="","",IF(EXACT(F7,(UPPER(F7))),"Account Upper Case","")) | T7: =IF(F7="","",IF(EXACT(F7,(LOWER(F7))),"Account Lower Case","")) | U7: =IF(EXACT(H7,PROPER(H7)),"","Billing Street - casing") | V7: =IF(EXACT(I7,PROPER(I7)),"","City - casing") | W7: =IF(OR(ISNUMBER(SEARCH("East",I7)),ISNUMBER(SEARCH("West",I7)),ISNUMBER(SEARCH("North",I7)),ISNUMBER(SEARCH("South",I7))),"",IF(OR(ISNUMBER(SEARCH("St.",I7)),ISNUMBER(SEARCH("St ",I7))),"Check St in city field",IF(RIGHT(I7,1)=".","Dot found in city field",""))) | X7: {=IF((SUMPRODUCT(--ISNUMBER(SEARCH({"!","@","#","$","%","^","&","~*","(",")","_","+","=","{","}","[","]","|","\",":",";","'","""","<",">",",",".","~?","/","~~","`"}, I7)))>0)=TRUE,"Special Characters Found in City","")} | Y7: {=IF((SUMPRODUCT(--ISNUMBER(SEARCH({"!","@","#","$","%","^","~*","(",")","_","+","=","{","}","[","]","|","\",":",";","'","""","<",">","~?","/","~~","`"},F7)))>0)=TRUE,"Special Characters Found in Account field","")} | Z7: {=IF(SUM(--ISNUMBER(SEARCH({1,2,3,4,5,6,7,8,9,0},MID(H7,(SEARCH(" E ",H7)-1),1))))+SUM(--ISNUMBER(SEARCH({1,2,3,4,5,6,7,8,9,0},MID(H7,(SEARCH(" E ",H7)+3),1))))=2,"",IF(SUM(--ISNUMBER(SEARCH({"Parte E","Apoquindo N"},H7)))>0,"",IF(OR(RIGHT(H7,3)=" NE",RIGHT(H7,3)=" NW",RIGHT(H7,3)=" SW",RIGHT(H7,3)=" SE",RIGHT(H7,2)=" N",RIGHT(H7,2)=" E",RIGHT(H7,2)=" W",RIGHT(H7,2)=" S",LEFT(H7,3)="NE ",LEFT(H7,3)="NW ",LEFT(H7,3)="SW ",LEFT(H7,3)="SE ",LEFT(H7,2)="N ",LEFT(H7,2)="E ",LEFT(H7,2)="W ",LEFT(H7,2)="S "),"Directional Check",IF(SUM(--ISNUMBER(SEARCH({" N "," E "," W "," S "," NE "," NW "," SW "," SE ","N.E","N.W","S.W","S.E","E.","N.","S.","W."},H7)))>0,"Directional Check",IF(SUM(--ISNUMBER(SEARCH({1,2,3,4,5,6,7,8,9,0},MID(H7,(SEARCH("nd ",H7)-1),1))))+SUM(--ISNUMBER(SEARCH({1,2,3,4,5,6,7,8,9,0},MID(H7,(SEARCH("rd ",H7)-1),1)))+SUM(--ISNUMBER(SEARCH({1,2,3,4,5,6,7,8,9,0},MID(H7,(SEARCH("st ",H7)-1),1))))+SUM(--ISNUMBER(SEARCH({1,2,3,4,5,6,7,8,9,0},MID(H7,(SEARCH("th ",H7)-1),1)))))>0,"","")))))} | AA7: =IF(IF(L7="US",IFERROR(VLOOKUP(J7,Country_Codes!$B:$B,1,0)=J7,"US State Code Error"),IF(L7="CA",IFERROR(VLOOKUP(J7,Country_Codes!$E:$E,1,0)=J7,"Canada State Code Error"),IF(L7="BR",IFERROR(VLOOKUP(J7,Country_Codes!$H:$H,1,0)=J7,"Brazil State Code Error"),IF(L7="AU",IFERROR(VLOOKUP(J7,Country_Codes!$K:$K,1,0)=J7,"Australia State Code Error"),""))))=TRUE,"",IF(L7="US",IFERROR(VLOOKUP(J7,Country_Codes!$B:$B,1,0)=J7,"US State Code Error"),IF(L7="CA",IFERROR(VLOOKUP(J7,Country_Codes!$E:$E,1,0)=J7,"Canada State Code Error"),IF(L7="BR",IFERROR(VLOOKUP(J7,Country_Codes!$H:$H,1,0)=J7,"Brazil State Code Error"),IF(L7="AU",IFERROR(VLOOKUP(J7,Country_Codes!$K:$K,1,0)=J7,"Australia State Code Error"),""))))) | AB7: =IF(OR(L7="US",L7="CA",L7="BR",L7="AU"),IF((EXACT(UPPER(J7),J7)),"","Country Code Casing"),IF(EXACT(J7,PROPER(J7)),"","Billing State casing")) | AC7: {=IFERROR(_xlfn.IFS(IF(AND(LEN(I7)=0,ISBLANK(I7)=FALSE),"",ISNUMBER(SEARCH(I7,H7))),"City/Postal Code/Country Found in Address",IF(AND(LEN(K7)=0,ISBLANK(K7)=FALSE),"",ISNUMBER(SEARCH(K7,H7))),"City/Postal Code/Country Found in Address",IF(AND(LEN(L7)=0,ISBLANK(L7)=FALSE),"",ISNUMBER(SEARCH(", "&L7,H7))),"City/Postal Code/Country Found in Address",IF(AND(LEN(J7)=0,ISBLANK(J7)=FALSE),"",ISNUMBER(SEARCH(", "&J7,H7))),"City/Postal Code/Country Found in Address",IF(AND(LEN(L7)=0,ISBLANK(L7)=FALSE),"",ISNUMBER(SEARCH(","&L7,H7))),"City/Postal Code/Country Found in Address",IF(AND(LEN(J7)=0,ISBLANK(J7)=FALSE),"",ISNUMBER(SEARCH(","&J7,H7))),"City/Postal Code/Country Found in Address"),"")} | AD7: =IF(ISNUMBER(SEARCH("PO",N7)),"PO# Entered in Tax ID Field","") | AE7: {=IFERROR(IF(VLOOKUP(LEFT(M7,MIN(SEARCH({1,2,3,4,5,6,7,8,9,0},M7&{1,2,3,4,5,6,7,8,9,0}))-1),Country_Codes!$N:$N,1,0)>0,"PO Number may be incorrect",""),"")} | AF7: =IF(N7="","",IF(EXACT(L7,LEFT(N7,2)),IF(EXACT(MID(N7,3,1)," "),"Check the Space inbetween County code & VAT",""),"Check the VAT Country Code Format")) | AG7: =IF((ISNUMBER(SEARCH("@",P7)))>0,"",IF(IF(--(ISNUMBER(SEARCH("'",P7)))>0,OR(EXACT(PROPER(P7),P7),EXACT((PROPER(LEFT(P7,FIND("'",P7)-2))&LOWER(MID(P7,FIND("'",P7)-1,1))&PROPER(MID(P7,FIND("'",P7)+0,LEN(P7)-FIND("'",P7)+1))),P7)),"Please check Billing Contact Casing")=TRUE,"","Please check Billing Contact casing")) | AH7: =IF(OR(L7="AS",L7="FM",L7="GU",L7="MH",L7="MP",L7="PW",L7="PR",L7="VI",L7="UM"),"US Territories Check","") | AI7: {=IF(G7="","",_xlfn.IFNA(_xlfn.IFS(L7=VLOOKUP(L7,Country_Codes!$M:$M,1,0)=TRUE,""),"Please check the country code"))} | AJ7: =IF(S7="","",S7&"; ")&IF(T7="","",T7&"; ")&IF(U7="","",U7&"; ")&IF(V7="","",V7&"; ")&IF(AF7="","",AF7&"; ")&IF(AG7="","",AG7&"; ")&IF(AH7="","",AH7&"; ")&IF(Z7="","",Z7&"; ")&IF(AA7="","",AA7&"; ")&IF(AB7="","",AB7&"; ")&IF(AC7="","",AC7&"; ")&IF(AD7="","",AD7&"; ")&IF(AE7="","",AE7&"; ")&IF(AI7="","",AI7&"; ")&IF(W7="","",W7&"; ")&IF(X7="","",X7&"; ")&IF(Y7="","",Y7&"; ") | AM7: =(COUNTA(S7:V7)-COUNTIFS((S7:V7),""))+(COUNTA(AB7)-COUNTIFS((AB7),""))+(COUNTA(AG7)-COUNTIFS((AG7),"")) -> 0 | AN7: =(COUNTA(W7)-COUNTIFS((W7),""))+(COUNTA(Z7)-COUNTIFS((Z7),"")) -> 0 | AO7: =(COUNTA(AA7)-COUNTIFS((AA7),""))+(COUNTA(AC7:AE7)-COUNTIFS((AC7:AE7),""))+(COUNTA(AH7:AI7)-COUNTIFS((AH7:AI7),"")) -> 0 | AP7: =(COUNTA(X7:Y7)-COUNTIFS((X7:Y7),""))+(COUNTA(AF7)-COUNTIFS((AF7),"")) -> 0 | AQ7: =SUM(AM7:AP7) -> 0 | AS7: Total | AT7: =SUM(AT3:AT6) -> 12 | AV7: 45424 | AW7: Sample Technologies, Inc.
A8: 45315 | B8: User 1 | C8: Bill To Contact | D8: ID-0005a000 | E8: ID-0006a000 | F8: Sample flow, inc. | G8: ID_Num_4 | H8: 11111 Sample Place | I8: Charlotte | J8: NC | K8: 28277 | L8: US | O8: Tony Frank | R8: =IF(G8=G7,"","Unique Record") -> Unique Record | S8: =IF(F8="","",IF(EXACT(F8,(UPPER(F8))),"Account Upper Case","")) | T8: =IF(F8="","",IF(EXACT(F8,(LOWER(F8))),"Account Lower Case","")) | U8: =IF(EXACT(H8,PROPER(H8)),"","Billing Street - casing") | V8: =IF(EXACT(I8,PROPER(I8)),"","City - casing") | W8: =IF(OR(ISNUMBER(SEARCH("East",I8)),ISNUMBER(SEARCH("West",I8)),ISNUMBER(SEARCH("North",I8)),ISNUMBER(SEARCH("South",I8))),"",IF(OR(ISNUMBER(SEARCH("St.",I8)),ISNUMBER(SEARCH("St ",I8))),"Check St in city field",IF(RIGHT(I8,1)=".","Dot found in city field",""))) | X8: {=IF((SUMPRODUCT(--ISNUMBER(SEARCH({"!","@","#","$","%","^","&","~*","(",")","_","+","=","{","}","[","]","|","\",":",";","'","""","<",">",",",".","~?","/","~~","`"}, I8)))>0)=TRUE,"Special Characters Found in City","")} | Y8: {=IF((SUMPRODUCT(--ISNUMBER(SEARCH({"!","@","#","$","%","^","~*","(",")","_","+","=","{","}","[","]","|","\",":",";","'","""","<",">","~?","/","~~","`"},F8)))>0)=TRUE,"Special Characters Found in Account field","")} | Z8: {=IF(SUM(--ISNUMBER(SEARCH({1,2,3,4,5,6,7,8,9,0},MID(H8,(SEARCH(" E ",H8)-1),1))))+SUM(--ISNUMBER(SEARCH({1,2,3,4,5,6,7,8,9,0},MID(H8,(SEARCH(" E ",H8)+3),1))))=2,"",IF(SUM(--ISNUMBER(SEARCH({"Parte E","Apoquindo N"},H8)))>0,"",IF(OR(RIGHT(H8,3)=" NE",RIGHT(H8,3)=" NW",RIGHT(H8,3)=" SW",RIGHT(H8,3)=" SE",RIGHT(H8,2)=" N",RIGHT(H8,2)=" E",RIGHT(H8,2)=" W",RIGHT(H8,2)=" S",LEFT(H8,3)="NE ",LEFT(H8,3)="NW ",LEFT(H8,3)="SW ",LEFT(H8,3)="SE ",LEFT(H8,2)="N ",LEFT(H8,2)="E ",LEFT(H8,2)="W ",LEFT(H8,2)="S "),"Directional Check",IF(SUM(--ISNUMBER(SEARCH({" N "," E "," W "," S "," NE "," NW "," SW "," SE ","N.E","N.W","S.W","S.E","E.","N.","S.","W."},H8)))>0,"Directional Check",IF(SUM(--ISNUMBER(SEARCH({1,2,3,4,5,6,7,8,9,0},MID(H8,(SEARCH("nd ",H8)-1),1))))+SUM(--ISNUMBER(SEARCH({1,2,3,4,5,6,7,8,9,0},MID(H8,(SEARCH("rd ",H8)-1),1)))+SUM(--ISNUMBER(SEARCH({1,2,3,4,5,6,7,8,9,0},MID(H8,(SEARCH("st ",H8)-1),1))))+SUM(--ISNUMBER(SEARCH({1,2,3,4,5,6,7,8,9,0},MID(H8,(SEARCH("th ",H8)-1),1)))))>0,"","")))))} | AA8: =IF(IF(L8="US",IFERROR(VLOOKUP(J8,Country_Codes!$B:$B,1,0)=J8,"US State Code Error"),IF(L8="CA",IFERROR(VLOOKUP(J8,Country_Codes!$E:$E,1,0)=J8,"Canada State Code Error"),IF(L8="BR",IFERROR(VLOOKUP(J8,Country_Codes!$H:$H,1,0)=J8,"Brazil State Code Error"),IF(L8="AU",IFERROR(VLOOKUP(J8,Country_Codes!$K:$K,1,0)=J8,"Australia State Code Error"),""))))=TRUE,"",IF(L8="US",IFERROR(VLOOKUP(J8,Country_Codes!$B:$B,1,0)=J8,"US State Code Error"),IF(L8="CA",IFERROR(VLOOKUP(J8,Country_Codes!$E:$E,1,0)=J8,"Canada State Code Error"),IF(L8="BR",IFERROR(VLOOKUP(J8,Country_Codes!$H:$H,1,0)=J8,"Brazil State Code Error"),IF(L8="AU",IFERROR(VLOOKUP(J8,Country_Codes!$K:$K,1,0)=J8,"Australia State Code Error"),""))))) | AB8: =IF(OR(L8="US",L8="CA",L8="BR",L8="AU"),IF((EXACT(UPPER(J8),J8)),"","Country Code Casing"),IF(EXACT(J8,PROPER(J8)),"","Billing State casing")) | AC8: {=IFERROR(_xlfn.IFS(IF(AND(LEN(I8)=0,ISBLANK(I8)=FALSE),"",ISNUMBER(SEARCH(I8,H8))),"City/Postal Code/Country Found in Address",IF(AND(LEN(K8)=0,ISBLANK(K8)=FALSE),"",ISNUMBER(SEARCH(K8,H8))),"City/Postal Code/Country Found in Address",IF(AND(LEN(L8)=0,ISBLANK(L8)=FALSE),"",ISNUMBER(SEARCH(", "&L8,H8))),"City/Postal Code/Country Found in Address",IF(AND(LEN(J8)=0,ISBLANK(J8)=FALSE),"",ISNUMBER(SEARCH(", "&J8,H8))),"City/Postal Code/Country Found in Address",IF(AND(LEN(L8)=0,ISBLANK(L8)=FALSE),"",ISNUMBER(SEARCH(","&L8,H8))),"City/Postal Code/Country Found in Address",IF(AND(LEN(J8)=0,ISBLANK(J8)=FALSE),"",ISNUMBER(SEARCH(","&J8,H8))),"City/Postal Code/Country Found in Address"),"")} | AD8: =IF(ISNUMBER(SEARCH("PO",N8)),"PO# Entered in Tax ID Field","") | AE8: {=IFERROR(IF(VLOOKUP(LEFT(M8,MIN(SEARCH({1,2,3,4,5,6,7,8,9,0},M8&{1,2,3,4,5,6,7,8,9,0}))-1),Country_Codes!$N:$N,1,0)>0,"PO Number may be incorrect",""),"")} | AF8: =IF(N8="","",IF(EXACT(L8,LEFT(N8,2)),IF(EXACT(MID(N8,3,1)," "),"Check the Space inbetween County code & VAT",""),"Check the VAT Country Code Format")) | AG8: =IF((ISNUMBER(SEARCH("@",P8)))>0,"",IF(IF(--(ISNUMBER(SEARCH("'",P8)))>0,OR(EXACT(PROPER(P8),P8),EXACT((PROPER(LEFT(P8,FIND("'",P8)-2))&LOWER(MID(P8,FIND("'",P8)-1,1))&PROPER(MID(P8,FIND("'",P8)+0,LEN(P8)-FIND("'",P8)+1))),P8)),"Please check Billing Contact Casing")=TRUE,"","Please check Billing Contact casing")) | AH8: =IF(OR(L8="AS",L8="FM",L8="GU",L8="MH",L8="MP",L8="PW",L8="PR",L8="VI",L8="UM"),"US Territories Check","") | AI8: {=IF(G8="","",_xlfn.IFNA(_xlfn.IFS(L8=VLOOKUP(L8,Country_Codes!$M:$M,1,0)=TRUE,""),"Please check the country code"))} | AJ8: =IF(S8="","",S8&"; ")&IF(T8="","",T8&"; ")&IF(U8="","",U8&"; ")&IF(V8="","",V8&"; ")&IF(AF8="","",AF8&"; ")&IF(AG8="","",AG8&"; ")&IF(AH8="","",AH8&"; ")&IF(Z8="","",Z8&"; ")&IF(AA8="","",AA8&"; ")&IF(AB8="","",AB8&"; ")&IF(AC8="","",AC8&"; ")&IF(AD8="","",AD8&"; ")&IF(AE8="","",AE8&"; ")&IF(AI8="","",AI8&"; ")&IF(W8="","",W8&"; ")&IF(X8="","",X8&"; ")&IF(Y8="","",Y8&"; ") | AM8: =(COUNTA(S8:V8)-COUNTIFS((S8:V8),""))+(COUNTA(AB8)-COUNTIFS((AB8),""))+(COUNTA(AG8)-COUNTIFS((AG8),"")) -> 0 | AN8: =(COUNTA(W8)-COUNTIFS((W8),""))+(COUNTA(Z8)-COUNTIFS((Z8),"")) -> 0 | AO8: =(COUNTA(AA8)-COUNTIFS((AA8),""))+(COUNTA(AC8:AE8)-COUNTIFS((AC8:AE8),""))+(COUNTA(AH8:AI8)-COUNTIFS((AH8:AI8),"")) -> 0 | AP8: =(COUNTA(X8:Y8)-COUNTIFS((X8:Y8),""))+(COUNTA(AF8)-COUNTIFS((AF8),"")) -> 0 | AQ8: =SUM(AM8:AP8) -> 0 | AV8: 45425 | AW8: Sample, Inc.
A9: 45622 | B9: User 1 | C9: Bill To Contact | D9: ID-0006a000 | F9: Sample Ltd | G9: ID_Num_5 | H9: main street, 5th Floor | I9: London | K9: EC2V 7EE | L9: GB | M9: PO 030 | P9: Smith Frank | R9: =IF(G9=G8,"","Unique Record") -> Unique Record | S9: =IF(F9="","",IF(EXACT(F9,(UPPER(F9))),"Account Upper Case","")) | T9: =IF(F9="","",IF(EXACT(F9,(LOWER(F9))),"Account Lower Case","")) | U9: =IF(EXACT(H9,PROPER(H9)),"","Billing Street - casing") -> Billing Street - casing | V9: =IF(EXACT(I9,PROPER(I9)),"","City - casing") | W9: =IF(OR(ISNUMBER(SEARCH("East",I9)),ISNUMBER(SEARCH("West",I9)),ISNUMBER(SEARCH("North",I9)),ISNUMBER(SEARCH("South",I9))),"",IF(OR(ISNUMBER(SEARCH("St.",I9)),ISNUMBER(SEARCH("St ",I9))),"Check St in city field",IF(RIGHT(I9,1)=".","Dot found in city field",""))) | X9: {=IF((SUMPRODUCT(--ISNUMBER(SEARCH({"!","@","#","$","%","^","&","~*","(",")","_","+","=","{","}","[","]","|","\",":",";","'","""","<",">",",",".","~?","/","~~","`"}, I9)))>0)=TRUE,"Special Characters Found in City","")} | Y9: {=IF((SUMPRODUCT(--ISNUMBER(SEARCH({"!","@","#","$","%","^","~*","(",")","_","+","=","{","}","[","]","|","\",":",";","'","""","<",">","~?","/","~~","`"},F9)))>0)=TRUE,"Special Characters Found in Account field","")} | Z9: {=IF(SUM(--ISNUMBER(SEARCH({1,2,3,4,5,6,7,8,9,0},MID(H9,(SEARCH(" E ",H9)-1),1))))+SUM(--ISNUMBER(SEARCH({1,2,3,4,5,6,7,8,9,0},MID(H9,(SEARCH(" E ",H9)+3),1))))=2,"",IF(SUM(--ISNUMBER(SEARCH({"Parte E","Apoquindo N"},H9)))>0,"",IF(OR(RIGHT(H9,3)=" NE",RIGHT(H9,3)=" NW",RIGHT(H9,3)=" SW",RIGHT(H9,3)=" SE",RIGHT(H9,2)=" N",RIGHT(H9,2)=" E",RIGHT(H9,2)=" W",RIGHT(H9,2)=" S",LEFT(H9,3)="NE ",LEFT(H9,3)="NW ",LEFT(H9,3)="SW ",LEFT(H9,3)="SE ",LEFT(H9,2)="N ",LEFT(H9,2)="E ",LEFT(H9,2)="W ",LEFT(H9,2)="S "),"Directional Check",IF(SUM(--ISNUMBER(SEARCH({" N "," E "," W "," S "," NE "," NW "," SW "," SE ","N.E","N.W","S.W","S.E","E.","N.","S.","W."},H9)))>0,"Directional Check",IF(SUM(--ISNUMBER(SEARCH({1,2,3,4,5,6,7,8,9,0},MID(H9,(SEARCH("nd ",H9)-1),1))))+SUM(--ISNUMBER(SEARCH({1,2,3,4,5,6,7,8,9,0},MID(H9,(SEARCH("rd ",H9)-1),1)))+SUM(--ISNUMBER(SEARCH({1,2,3,4,5,6,7,8,9,0},MID(H9,(SEARCH("st ",H9)-1),1))))+SUM(--ISNUMBER(SEARCH({1,2,3,4,5,6,7,8,9,0},MID(H9,(SEARCH("th ",H9)-1),1)))))>0,"","")))))} | AA9: =IF(IF(L9="US",IFERROR(VLOOKUP(J9,Country_Codes!$B:$B,1,0)=J9,"US State Code Error"),IF(L9="CA",IFERROR(VLOOKUP(J9,Country_Codes!$E:$E,1,0)=J9,"Canada State Code Error"),IF(L9="BR",IFERROR(VLOOKUP(J9,Country_Codes!$H:$H,1,0)=J9,"Brazil State Code Error"),IF(L9="AU",IFERROR(VLOOKUP(J9,Country_Codes!$K:$K,1,0)=J9,"Australia State Code Error"),""))))=TRUE,"",IF(L9="US",IFERROR(VLOOKUP(J9,Country_Codes!$B:$B,1,0)=J9,"US State Code Error"),IF(L9="CA",IFERROR(VLOOKUP(J9,Country_Codes!$E:$E,1,0)=J9,"Canada State Code Error"),IF(L9="BR",IFERROR(VLOOKUP(J9,Country_Codes!$H:$H,1,0)=J9,"Brazil State Code Error"),IF(L9="AU",IFERROR(VLOOKUP(J9,Country_Codes!$K:$K,1,0)=J9,"Australia State Code Error"),""))))) | AB9: =IF(OR(L9="US",L9="CA",L9="BR",L9="AU"),IF((EXACT(UPPER(J9),J9)),"","Country Code Casing"),IF(EXACT(J9,PROPER(J9)),"","Billing State casing")) | AC9: {=IFERROR(_xlfn.IFS(IF(AND(LEN(I9)=0,ISBLANK(I9)=FALSE),"",ISNUMBER(SEARCH(I9,H9))),"City/Postal Code/Country Found in Address",IF(AND(LEN(K9)=0,ISBLANK(K9)=FALSE),"",ISNUMBER(SEARCH(K9,H9))),"City/Postal Code/Country Found in Address",IF(AND(LEN(L9)=0,ISBLANK(L9)=FALSE),"",ISNUMBER(SEARCH(", "&L9,H9))),"City/Postal Code/Country Found in Address",IF(AND(LEN(J9)=0,ISBLANK(J9)=FALSE),"",ISNUMBER(SEARCH(", "&J9,H9))),"City/Postal Code/Country Found in Address",IF(AND(LEN(L9)=0,ISBLANK(L9)=FALSE),"",ISNUMBER(SEARCH(","&L9,H9))),"City/Postal Code/Country Found in Address",IF(AND(LEN(J9)=0,ISBLANK(J9)=FALSE),"",ISNUMBER(SEARCH(","&J9,H9))),"City/Postal Code/Country Found in Address"),"")} | AD9: =IF(ISNUMBER(SEARCH("PO",N9)),"PO# Entered in Tax ID Field","") | AE9: {=IFERROR(IF(VLOOKUP(LEFT(M9,MIN(SEARCH({1,2,3,4,5,6,7,8,9,0},M9&{1,2,3,4,5,6,7,8,9,0}))-1),Country_Codes!$N:$N,1,0)>0,"PO Number may be incorrect",""),"")} | AF9: =IF(N9="","",IF(EXACT(L9,LEFT(N9,2)),IF(EXACT(MID(N9,3,1)," "),"Check the Space inbetween County code & VAT",""),"Check the VAT Country Code Format")) | AG9: =IF((ISNUMBER(SEARCH("@",P9)))>0,"",IF(IF(--(ISNUMBER(SEARCH("'",P9)))>0,OR(EXACT(PROPER(P9),P9),EXACT((PROPER(LEFT(P9,FIND("'",P9)-2))&LOWER(MID(P9,FIND("'",P9)-1,1))&PROPER(MID(P9,FIND("'",P9)+0,LEN(P9)-FIND("'",P9)+1))),P9)),"Please check Billing Contact Casing")=TRUE,"","Please check Billing Contact casing")) | AH9: =IF(OR(L9="AS",L9="FM",L9="GU",L9="MH",L9="MP",L9="PW",L9="PR",L9="VI",L9="UM"),"US Territories Check","") | AI9: {=IF(G9="","",_xlfn.IFNA(_xlfn.IFS(L9=VLOOKUP(L9,Country_Codes!$M:$M,1,0)=TRUE,""),"Please check the country code"))} | AJ9: =IF(S9="","",S9&"; ")&IF(T9="","",T9&"; ")&IF(U9="","",U9&"; ")&IF(V9="","",V9&"; ")&IF(AF9="","",AF9&"; ")&IF(AG9="","",AG9&"; ")&IF(AH9="","",AH9&"; ")&IF(Z9="","",Z9&"; ")&IF(AA9="","",AA9&"; ")&IF(AB9="","",AB9&"; ")&IF(AC9="","",AC9&"; ")&IF(AD9="","",AD9&"; ")&IF(AE9="","",AE9&"; ")&IF(AI9="","",AI9&"; ")&IF(W9="","",W9&"; ")&IF(X9="","",X9&"; ")&IF(Y9="","",Y9&"; ") -> Billing Street - casing; | AM9: =(COUNTA(S9:V9)-COUNTIFS((S9:V9),""))+(COUNTA(AB9)-COUNTIFS((AB9),""))+(COUNTA(AG9)-COUNTIFS((AG9),"")) -> 1 | AN9: =(COUNTA(W9)-COUNTIFS((W9),""))+(COUNTA(Z9)-COUNTIFS((Z9),"")) -> 0 | AO9: =(COUNTA(AA9)-COUNTIFS((AA9),""))+(COUNTA(AC9:AE9)-COUNTIFS((AC9:AE9),""))+(COUNTA(AH9:AI9)-COUNTIFS((AH9:AI9),"")) -> 0 | AP9: =(COUNTA(X9:Y9)-COUNTIFS((X9:Y9),""))+(COUNTA(AF9)-COUNTIFS((AF9),"")) -> 0 | AQ9: =SUM(AM9:AP9) -> 1 | AV9: 45426 | AW9: SampleCo Ltd
A10: 45622 | B10: User 1 | C10: Billing Contact Name | E10: Smith Francis | F10: Sample Ltd | G10: ID_Num_5 | H10: Main Street | I10: London | K10: EC2V 7EE | L10: GB | M10: PO 030 | P10: Smith Frank | R10: =IF(G10=G9,"","Unique Record") | S10: =IF(F10="","",IF(EXACT(F10,(UPPER(F10))),"Account Upper Case","")) | T10: =IF(F10="","",IF(EXACT(F10,(LOWER(F10))),"Account Lower Case","")) | U10: =IF(EXACT(H10,PROPER(H10)),"","Billing Street - casing") | V10: =IF(EXACT(I10,PROPER(I10)),"","City - casing") | W10: =IF(OR(ISNUMBER(SEARCH("East",I10)),ISNUMBER(SEARCH("West",I10)),ISNUMBER(SEARCH("North",I10)),ISNUMBER(SEARCH("South",I10))),"",IF(OR(ISNUMBER(SEARCH("St.",I10)),ISNUMBER(SEARCH("St ",I10))),"Check St in city field",IF(RIGHT(I10,1)=".","Dot found in city field",""))) | X10: {=IF((SUMPRODUCT(--ISNUMBER(SEARCH({"!","@","#","$","%","^","&","~*","(",")","_","+","=","{","}","[","]","|","\",":",";","'","""","<",">",",",".","~?","/","~~","`"}, I10)))>0)=TRUE,"Special Characters Found in City","")} | Y10: {=IF((SUMPRODUCT(--ISNUMBER(SEARCH({"!","@","#","$","%","^","~*","(",")","_","+","=","{","}","[","]","|","\",":",";","'","""","<",">","~?","/","~~","`"},F10)))>0)=TRUE,"Special Characters Found in Account field","")} | Z10: {=IF(SUM(--ISNUMBER(SEARCH({1,2,3,4,5,6,7,8,9,0},MID(H10,(SEARCH(" E ",H10)-1),1))))+SUM(--ISNUMBER(SEARCH({1,2,3,4,5,6,7,8,9,0},MID(H10,(SEARCH(" E ",H10)+3),1))))=2,"",IF(SUM(--ISNUMBER(SEARCH({"Parte E","Apoquindo N"},H10)))>0,"",IF(OR(RIGHT(H10,3)=" NE",RIGHT(H10,3)=" NW",RIGHT(H10,3)=" SW",RIGHT(H10,3)=" SE",RIGHT(H10,2)=" N",RIGHT(H10,2)=" E",RIGHT(H10,2)=" W",RIGHT(H10,2)=" S",LEFT(H10,3)="NE ",LEFT(H10,3)="NW ",LEFT(H10,3)="SW ",LEFT(H10,3)="SE ",LEFT(H10,2)="N ",LEFT(H10,2)="E ",LEFT(H10,2)="W ",LEFT(H10,2)="S "),"Directional Check",IF(SUM(--ISNUMBER(SEARCH({" N "," E "," W "," S "," NE "," NW "," SW "," SE ","N.E","N.W","S.W","S.E","E.","N.","S.","W."},H10)))>0,"Directional Check",IF(SUM(--ISNUMBER(SEARCH({1,2,3,4,5,6,7,8,9,0},MID(H10,(SEARCH("nd ",H10)-1),1))))+SUM(--ISNUMBER(SEARCH({1,2,3,4,5,6,7,8,9,0},MID(H10,(SEARCH("rd ",H10)-1),1)))+SUM(--ISNUMBER(SEARCH({1,2,3,4,5,6,7,8,9,0},MID(H10,(SEARCH("st ",H10)-1),1))))+SUM(--ISNUMBER(SEARCH({1,2,3,4,5,6,7,8,9,0},MID(H10,(SEARCH("th ",H10)-1),1)))))>0,"","")))))} | AA10: =IF(IF(L10="US",IFERROR(VLOOKUP(J10,Country_Codes!$B:$B,1,0)=J10,"US State Code Error"),IF(L10="CA",IFERROR(VLOOKUP(J10,Country_Codes!$E:$E,1,0)=J10,"Canada State Code Error"),IF(L10="BR",IFERROR(VLOOKUP(J10,Country_Codes!$H:$H,1,0)=J10,"Brazil State Code Error"),IF(L10="AU",IFERROR(VLOOKUP(J10,Country_Codes!$K:$K,1,0)=J10,"Australia State Code Error"),""))))=TRUE,"",IF(L10="US",IFERROR(VLOOKUP(J10,Country_Codes!$B:$B,1,0)=J10,"US State Code Error"),IF(L10="CA",IFERROR(VLOOKUP(J10,Country_Codes!$E:$E,1,0)=J10,"Canada State Code Error"),IF(L10="BR",IFERROR(VLOOKUP(J10,Country_Codes!$H:$H,1,0)=J10,"Brazil State Code Error"),IF(L10="AU",IFERROR(VLOOKUP(J10,Country_Codes!$K:$K,1,0)=J10,"Australia State Code Error"),""))))) | AB10: =IF(OR(L10="US",L10="CA",L10="BR",L10="AU"),IF((EXACT(UPPER(J10),J10)),"","Country Code Casing"),IF(EXACT(J10,PROPER(J10)),"","Billing State casing")) | AC10: {=IFERROR(_xlfn.IFS(IF(AND(LEN(I10)=0,ISBLANK(I10)=FALSE),"",ISNUMBER(SEARCH(I10,H10))),"City/Postal Code/Country Found in Address",IF(AND(LEN(K10)=0,ISBLANK(K10)=FALSE),"",ISNUMBER(SEARCH(K10,H10))),"City/Postal Code/Country Found in Address",IF(AND(LEN(L10)=0,ISBLANK(L10)=FALSE),"",ISNUMBER(SEARCH(", "&L10,H10))),"City/Postal Code/Country Found in Address",IF(AND(LEN(J10)=0,ISBLANK(J10)=FALSE),"",ISNUMBER(SEARCH(", "&J10,H10))),"City/Postal Code/Country Found in Address",IF(AND(LEN(L10)=0,ISBLANK(L10)=FALSE),"",ISNUMBER(SEARCH(","&L10,H10))),"City/Postal Code/Country Found in Address",IF(AND(LEN(J10)=0,ISBLANK(J10)=FALSE),"",ISNUMBER(SEARCH(","&J10,H10))),"City/Postal Code/Country Found in Address"),"")} | AD10: =IF(ISNUMBER(SEARCH("PO",N10)),"PO# Entered in Tax ID Field","") | AE10: {=IFERROR(IF(VLOOKUP(LEFT(M10,MIN(SEARCH({1,2,3,4,5,6,7,8,9,0},M10&{1,2,3,4,5,6,7,8,9,0}))-1),Country_Codes!$N:$N,1,0)>0,"PO Number may be incorrect",""),"")} | AF10: =IF(N10="","",IF(EXACT(L10,LEFT(N10,2)),IF(EXACT(MID(N10,3,1)," "),"Check the Space inbetween County code & VAT",""),"Check the VAT Country Code Format")) | AG10: =IF((ISNUMBER(SEARCH("@",P10)))>0,"",IF(IF(--(ISNUMBER(SEARCH("'",P10)))>0,OR(EXACT(PROPER(P10),P10),EXACT((PROPER(LEFT(P10,FIND("'",P10)-2))&LOWER(MID(P10,FIND("'",P10)-1,1))&PROPER(MID(P10,FIND("'",P10)+0,LEN(P10)-FIND("'",P10)+1))),P10)),"Please check Billing Contact Casing")=TRUE,"","Please check Billing Contact casing")) | AH10: =IF(OR(L10="AS",L10="FM",L10="GU",L10="MH",L10="MP",L10="PW",L10="PR",L10="VI",L10="UM"),"US Territories Check","") | AI10: {=IF(G10="","",_xlfn.IFNA(_xlfn.IFS(L10=VLOOKUP(L10,Country_Codes!$M:$M,1,0)=TRUE,""),"Please check the country code"))} | AJ10: =IF(S10="","",S10&"; ")&IF(T10="","",T10&"; ")&IF(U10="","",U10&"; ")&IF(V10="","",V10&"; ")&IF(AF10="","",AF10&"; ")&IF(AG10="","",AG10&"; ")&IF(AH10="","",AH10&"; ")&IF(Z10="","",Z10&"; ")&IF(AA10="","",AA10&"; ")&IF(AB10="","",AB10&"; ")&IF(AC10="","",AC10&"; ")&IF(AD10="","",AD10&"; ")&IF(AE10="","",AE10&"; ")&IF(AI10="","",AI10&"; ")&IF(W10="","",W10&"; ")&IF(X10="","",X10&"; ")&IF(Y10="","",Y10&"; ") | AM10: =(COUNTA(S10:V10)-COUNTIFS((S10:V10),""))+(COUNTA(AB10)-COUNTIFS((AB10),""))+(COUNTA(AG10)-COUNTIFS((AG10),"")) -> 0 | AN10: =(COUNTA(W10)-COUNTIFS((W10),""))+(COUNTA(Z10)-COUNTIFS((Z10),"")) -> 0 | AO10: =(COUNTA(AA10)-COUNTIFS((AA10),""))+(COUNTA(AC10:AE10)-COUNTIFS((AC10:AE10),""))+(COUNTA(AH10:AI10)-COUNTIFS((AH10:AI10),"")) -> 0 | AP10: =(COUNTA(X10:Y10)-COUNTIFS((X10:Y10),""))+(COUNTA(AF10)-COUNTIFS((AF10),"")) -> 0 | AQ10: =SUM(AM10:AP10) -> 0 | AV10: 45427 | AW10: SampleCo Partners
